<!DOCTYPE html>
<html dir="ltr" lang="en-gb">

<!-- Mirrored from forum.abinit.org/viewtopic.php?f=19&t=2980&view=print by HTTrack Website Copier/3.x [XR&CO'2014], Fri, 20 Sep 2024 21:58:18 GMT -->
<!-- Added by HTTrack --><meta http-equiv="content-type" content="text/html;charset=UTF-8" /><!-- /Added by HTTrack -->
<head>
<meta charset="utf-8" />
<meta http-equiv="X-UA-Compatible" content="IE=edge">
<meta name="robots" content="noindex" />

<title>ABINIT Discussion Forums &bull; runtests.py failure</title>

<link href="styles/flat-style/theme/print.css" rel="stylesheet">
<link href="styles/flat-style/theme/bidi.css" rel="stylesheet">
</head>
<body id="phpbb" class="ltr">
<div id="wrap" class="wrap">
	<a id="top" class="top-anchor" accesskey="t"></a>

	<div id="page-header">
		<h1>ABINIT Discussion Forums</h1>
		<p>The meeting place for ABINIT users and developers<br /><a href="index.html">https://forum.abinit.org/</a></p>

		<h2>runtests.py failure</h2>
		<p><a href="viewtopicbe58.html?f=19&amp;t=2980">https://forum.abinit.org/viewtopic.php?f=19&amp;t=2980</a></p>
	</div>

	<div id="page-body" class="page-body">
		<div class="page-number">Page <strong>1</strong> of <strong>1</strong></div>
					<div class="post">
				<h3>runtests.py failure</h3>
				<div class="date">Posted: <strong>Tue May 05, 2015 6:28 pm</strong></div>
				<div class="author">by <strong>jzwanzig</strong></div>
				<div class="content">Hi, when I execute runtests.py with the -i option I keep getting a KeyError failure as follows:<br /><br />../../tests/runtests.py -i 'rfddk'<br /><br />OUTPUT:<br />FortranCompiler: intel None<br />Traceback (most recent call last):<br />  File &quot;../../tests/runtests.py&quot;, line 479, in &lt;module&gt;<br />    sys.exit(main())<br />  File &quot;../../tests/runtests.py&quot;, line 368, in main<br />    ivars=ivars, with_pickle=options.with_pickle)<br />  File &quot;/home/jzwanzig/code/abinit/7.11/7.11.6-private/tests/__init__.py&quot;, line 684, in select_tests<br />    tests = tests + database.get_test_suite(suite_name, subsuite_name=subsuite_name, slice_obj=slice_obj)<br />  File &quot;/home/jzwanzig/code/abinit/7.11/7.11.6-private/tests/__init__.py&quot;, line 266, in get_test_suite<br />    test_suite = self[suite_name]<br />KeyError: 'bigdft_paral'<br /><br />Suggestions for how to fix?<br /><br />thanks,<br />joe</div>
			</div>
			<hr />
					<div class="post">
				<h3>Re: runtests.py failure</h3>
				<div class="date">Posted: <strong>Thu May 07, 2015 11:28 am</strong></div>
				<div class="author">by <strong>gmatteo</strong></div>
				<div class="content">Hi Joe,<br /><br />have you tried to regenerate the pickle database?<br />Use<br /><br />./runtests.py -r -i 'rfddk'</div>
			</div>
			<hr />
					<div class="post">
				<h3>Re: runtests.py failure</h3>
				<div class="date">Posted: <strong>Thu May 07, 2015 3:27 pm</strong></div>
				<div class="author">by <strong>jzwanzig</strong></div>
				<div class="content">that worked, Matteo, thanks! is it possible to have the script provide a more informative error message when this happens?<br /><br />thanks,<br />Joe</div>
			</div>
			<hr />
			</div>

	<div id="page-footer" class="page-footer">
		<div class="page-number">All times are <span title="Europe/Brussels">UTC+02:00</span><br />Page <strong>1</strong> of <strong>1</strong></div>
			<div class="copyright">
				<p>Powered by <a href="https://www.phpbb.com/">phpBB</a>&reg; Forum Software &copy; phpBB Limited
				</p>
							</div>
	</div>
</div>

</body>

<!-- Mirrored from forum.abinit.org/viewtopic.php?f=19&t=2980&view=print by HTTrack Website Copier/3.x [XR&CO'2014], Fri, 20 Sep 2024 21:58:18 GMT -->
</html>
